<mujoco model="planar point mass">
  <include file="./common/skybox.xml"/>
  <include file="./common/visual.xml"/>
  <include file="./common/materials.xml"/>

  <option timestep="0.02">
    <flag contact="disable"/>
  </option>

  <worldbody>

    <!-- <geom name="ground" type="plane" pos="0 0 0" size=".3 .3 .1" material="grid"/> -->

    <body name="pointmass" pos="0.8 -0.4 .01">
      <joint name="root_x" type="slide"  pos="0 0 0" axis="1 0 0" />
      <joint name="root_y" type="slide"  pos="0 0 0" axis="0 1 0" />
      <geom name="pointmass" type="sphere" size=".04" material="self" mass=".3"/>
    </body>

    <!-- <geom name="target" pos="0 0.5 .01" material="target" type="sphere" size=".015"/> -->
  </worldbody>

  <tendon>
    <fixed name="t1">
      <joint joint="root_x" coef="1"/>
      <joint joint="root_y" coef="0"/>
    </fixed>
    <fixed name="t2">
      <joint joint="root_x" coef="0"/>
      <joint joint="root_y" coef="1"/>
    </fixed>
  </tendon>

  <actuator>
    <motor name="t1" tendon="t1"/>
    <motor name="t2" tendon="t2"/>
  </actuator>
</mujoco>
